Workbook

Sheet Jan
B3: FUEL | E3: Salary | G3: Maintenance | J3: Revenue
A4: PM 4 | B4: PO No. / Ref | C4: DATE | D4: Amount | E4: Date | F4: Amount | G4: Ref | H4: Description | I4: Amount
A5: week 1 | B5: 2026-01 | D5: 18414 | E5: JAN 2-9,2026 | F5: 11220
A6: week 2 | B6: 2026-02 | D6: 12086 | E6: JAN 10-16,2026 | F6: 12770
A7: week 3 | B7: 2026-03 | D7: 9094.5 | E7: JAN 17-23,2026 | F7: 10545
A8: week 4 | B8: 2026-05 | D8: 12526 | E8: JAN 24-30,2026 | F8: 9285
A9: week 5 | B9: 2026-07 | D9: 10885.1
A12: Total | D12: =SUM(D5:D11) -> 63005.6 | F12: =SUM(F5:F11) -> 43820 | I12: =SUM(I5:I11) -> 0
B13: FUEL | E13: Salary | G13: Maintenance
A14: PM 5 | B14: PO No. / Ref | C14: DATE | D14: Amount | E14: Date | F14: Amount | G14: Ref | H14: Description | I14: Amount
A15: week 1 | B15: 2026-01 | D15: 18414 | E15: JAN 2-9,2026 | F15: 8255
A16: week 2 | B16: 2026-02 | D16: 6043 | E16: JAN 10-16,2026 | F16: 7300
A17: week 3 | B17: 2026-03 | D17: 9094.5 | E17: JAN 17-23,2026 | F17: 10145
A18: week 4 | B18: 2026-04 | D18: 12126 | E18: JAN 24-30,2026 | F18: 10760
A19: week 5 | B19: 2026-07 | D19: 10885.1
D22: =SUM(D15:D19) -> 56562.6 | F22: =SUM(F15:F19) -> 36460 | I22: =SUM(I15:I19) -> 0
B23: FUEL | E23: Salary | G23: Maintenance
A24: PM 6 | B24: PO No. / Ref | C24: DATE | D24: Amount | E24: Date | F24: Amount | G24: Ref | H24: Description | I24: Amount
A25: week 1
A26: week 2
A27: week 3 | D27: 16007.5 | E27: JAN 17-23,2026 | F27: 2315
A28: week 4 | B28: 2026-06 | D28: 9604.5 | E28: JAN 24-30,2026 | F28: 11720
A29: week 5 | B29: 2026-07
D32: =SUM(D25:D29) -> 25612 | F32: =SUM(F25:F29) -> 14035 | I32: =SUM(I25:I29) -> 0
B33: FUEL | E33: Salary | G33: Maintenance
A34: PM 7 | B34: PO No. / Ref | C34: DATE | D34: Amount | E34: Date | F34: Amount | G34: Ref | H34: Description | I34: Amount
A35: week 1 | B35: 2026-01 | D35: 21483 | E35: JAN 2-9,2026 | F35: 8355
A36: week 2 | B36: 2026-02 | D36: 9064.5 | E36: JAN 10-16,2026 | F36: 7110
A37: week 3 | B37: 2026-03 | E37: JAN 17-23,2026 | F37: 10785
A38: week 4 | B38: 2026-05 | D38: 12526 | E38: JAN 24-30,2026 | F38: 8835
A39: week 5
B42: FUEL | E42: Salary | G42: Maintenance | J42: Revenue
A43: PM 5 | B43: PO No. / Ref | C43: DATE | D43: Amount | E43: Date | F43: Amount | G43: Ref | H43: Description | I43: Amount
A44: week 6 | B44: 2026-01 | D44: 5292.22 | E44: JAN 2-9,2027 | F44: 6538.5
A45: week 7 | B45: 2026-02 | D45: 3830.44 | E45: JAN 10-16,2027 | F45: 5735.5
A46: week 8 | B46: 2026-03 | D46: 2368.66 | E46: JAN 17-23,2027 | F46: 4932.5
A47: week 9 | B47: 2026-05 | D47: 906.88 | E47: JAN 24-30,2027 | F47: 4129.5
A48: week 10 | B48: 2026-07 | D48: -554.9
A51: Total | D51: =SUM(D44:D50) -> 11843.3 | F51: =SUM(F44:F50) -> 21336 | I51: =SUM(I44:I50) -> 0
B52: FUEL | E52: Salary | G52: Maintenance
...

Sheet Feb
B3: FUEL | E3: Salary | G3: Maintenance
A4: PM 4 | B4: PO No. / Ref | C4: DATE | D4: Amount | E4: Date | F4: Amount | G4: Ref | H4: Description | I4: Amount | J4: Date | K4: Amount
A5: week 1 | B5: 2026-08 | D5: 13126 | E5: JAN 31-FEB 6,2026 | F5: 11985 | J5: Jan 3-9,2026 | K5: 101700
A6: week 2 | B6: 2026-11 | D6: 13326 | E6: FEB 7-13,2026
A7: week 3 | B7: 2026-13 | D7: 10129 | E7: FEB 14-20,2026 | F7: 5590
A8: week 4 | B8: 2026-16 | D8: 12986 | E8: FEB 21-27,2026 | F8: 5400
A9: week 5
B13: FUEL | E13: Salary | G13: Maintenance
A14: PM 5 | B14: PO No. / Ref | C14: DATE | D14: Amount | E14: Date | F14: Amount | G14: Ref | H14: Description | I14: Amount
A15: week 1 | E15: JAN 31-FEB 6,2026 | F15: 7045
A16: week 2 | B16: 2026-10 | D16: 6563 | E16: FEB 7-13,2026
A17: week 3 | B17: 2026-13 | D17: 12506 | E17: FEB 14-20,2026 | F17: 12052.8
A18: week 4 | B18: 2026-14 | D18: 19419 | E18: FEB 21-27,2026 | F18: 8555
A19: week 5
B23: FUEL | E23: Salary | G23: Maintenance
A24: PM 6 | B24: PO No. / Ref | C24: DATE | D24: Amount | E24: Date | F24: Amount | G24: Ref | H24: Description | I24: Amount
A25: week 1 | B25: 2026-08 | D25: 11485.25 | E25: JAN 31-FEB 6,2026 | F25: 8460
A26: week 2 | E26: FEB 7-13,2026
A27: week 3 | B27: 2026-13 | D27: 16882.5 | E27: FEB 14-20,2026 | F27: 10403
A28: week 4 | B28: 2026-15 | D28: 12946 | E28: FEB 21-27,2026 | F28: 8360
A29: week 5
B33: FUEL | E33: Salary | G33: Maintenance
A34: PM 7 | B34: PO No. / Ref | C34: DATE | D34: Amount | E34: Date | F34: Amount | G34: Ref | H34: Description | I34: Amount
A35: week 1 | B35: 2026-07 & 08 | D35: 24699.4 | E35: JAN 31-FEB 6,2026 | F35: 7955
A36: week 2 | B36: 2026-11 | D36: 13326 | E36: FEB 7-13,2026
A37: week 3 | B37: 2026-14 | D37: 12946 | E37: FEB 14-20,2026 | F37: 8095
A38: week 4 | B38: 2026-16 | D38: 9739.5 | E38: FEB 21-27,2026 | F38: 9365
A39: week 5

Sheet March
A2: 46082
B3: FUEL | E3: Salary | G3: Maintenance
A4: PM 4 | B4: PO No. / Ref | C4: DATE | D4: Amount | E4: Date | F4: Amount | G4: Ref | H4: Description | I4: Amount
A5: week 1 | B5: 2026-17 | D5: 10338.8 | E5: FEB 28-MARCH 6,2026 | F5: 10293
A6: week 2 | B6: 2026-18 | D6: 21987.5 | E6: MARCH 7-13,2026 | F6: 12545
A7: week 3 | E7: MARCH 14-20,2026 | F7: 7555
A8: week 4 | B8: 2026-23 | D8: 11220 | E8: MARCH 21-27,2026 | F8: 6290
A9: week 5 | E9: MARCH 28- APRIL 3,2026 | F9: 5585
D12: =SUM(D5:D9) -> 43546.3 | F12: =SUM(F5:F9) -> 42268
B13: FUEL | E13: Salary | G13: Maintenance
A14: PM 5 | B14: PO No. / Ref | C14: DATE | D14: Amount | E14: Date | F14: Amount | G14: Ref | H14: Description | I14: Amount
A15: week 1 | B15: 2026-17 | D15: 14933.9 | E15: FEB 28-MARCH 6,2026 | F15: 8793
A16: week 2 | E16: MARCH 7-13,2026 | F16: 5870
A17: week 3 | B17: 2026-19 | D17: 16710 | E17: MARCH 14-20,2026 | F17: 8460
A18: week 4 | B18: 2026-23 | D18: 20196 | E18: MARCH 21-27,2026 | F18: 9060
A19: week 5 | B19: 2026-0001 | D19: 34000 | E19: MARCH 28- APRIL 3,2026 | F19: 6725
D21: =SUM(D15:D19) -> 85839.9 | F21: =SUM(F15:F19) -> 38908
B22: FUEL | E22: Salary | G22: Maintenance
A23: PM 6 | B23: PO No. / Ref | C23: DATE | D23: Amount | E23: Date | F23: Amount | G23: Ref | H23: Description | I23: Amount
A24: week 1 | B24: 2026-17 | D24: 21426.9 | E24: FEB 28-MARCH 6,2026 | F24: 11378
A25: week 2 | E25: MARCH 7-13,2026 | F25: 8415
A26: week 3 | B26: 2026-19 | D26: 18909.25 | E26: MARCH 14-20,2026 | F26: 9376
A27: week 4 | B27: 2026-23 | D27: 41514 | E27: MARCH 21-27,2026 | F27: 7110
A28: week 5 | B28: 2026-0002 | D28: 25500 | E28: MARCH 28- APRIL 3,2026 | F28: 4670
D30: =SUM(D24:D28) -> 107350.15 | F30: =SUM(F24:F28) -> 40949
B31: FUEL | E31: Salary | G31: Maintenance
A32: PM 7 | B32: PO No. / Ref | C32: DATE | D32: Amount | E32: Date | F32: Amount | G32: Ref | H32: Description | I32: Amount
A33: week 1 | B33: 2026-17 | D33: 19479 | E33: FEB 28-MARCH 6,2026 | F33: 9096.5
A34: week 2 | E34: MARCH 7-13,2026 | F34: 8733.5
A35: week 3 | B35: 2026-19 | D35: 18029.75 | E35: MARCH 14-20,2026 | F35: 10381
A36: week 4 | B36: 2026-23 | D36: 22440 | E36: MARCH 21-27,2026 | F36: 7410
A37: week 5 | E37: MARCH 28- APRIL 3,2026 | F37: 5665
D39: =SUM(D33:D37) -> 59948.75 | F39: =SUM(F33:F37) -> 41286

Sheet April 
A2: 46113
B3: FUEL | F3: Salary | H3: Maintenance
A4: PM 4 | B4: PO No. / Ref | C4: DATE | D4: Amount | E4: Liter | F4: Date | G4: Amount | H4: Ref | I4: Description | J4: Amount
A5: week 1 | B5: 2026-0003 | D5: 51000 | E5: 300 | F5: APRIL 4 - APRIL 10 ,2026 | G5: 5360
A6: week 2 | B6: 2026-0011 | D6: 22500 | E6: 150 | F6: APRIL 11 - APRIL17 ,2026 | G6: 3280
A7: week 3 | B7: 2026-0014 | D7: 20392 | E7: 200 | F7: APRIL 18 - APRIL 24, 2026 | G7: 8305
A8: week 4 | F8: APRIL 25- MAY 1, 2026 | G8: 6140
A9: week 5
D12: =SUM(D5:D9) -> 93892 | E12: =SUM(E5:E9) -> 650 | G12: =SUM(G5:G9) -> 23085
B13: FUEL | F13: Salary | H13: Maintenance
A14: PM 5 | B14: PO No. / Ref | C14: DATE | D14: Amount | E14: Liter | F14: Date | G14: Amount | H14: Ref | I14: Description | J14: Amount
A15: week 1 | B15: 2026-0005 | D15: 4500 | E15: 30 | F15: APRIL 4 - APRIL 10 ,2026 | G15: 4895
A16: week 2 | B16: 2026-0012 | D16: 22500 | E16: 124 | F16: APRIL 11 - APRIL17 ,2026 | G16: 4750
A17: week 3 | F17: APRIL 18 - APRIL 24, 2026 | G17: 7750
A18: week 4 | B18: 2026-0016 | D18: 18120 | E18: 200 | F18: APRIL 25- MAY 1, 2026 | G18: 6140
A19: week 5
D21: =SUM(D15:D19) -> 45120 | E21: =SUM(E15:E19) -> 354 | G21: =SUM(G15:G19) -> 23535
B22: FUEL | F22: Salary | H22: Maintenance
A23: PM 6 | B23: PO No. / Ref | C23: DATE | D23: Amount | E23: Liter | F23: Date | G23: Amount | H23: Ref | I23: Description | J23: Amount
A24: week 1 | B24: 2026-0006 | D24: 8250 | E24: 55 | F24: APRIL 4 - APRIL 10 ,2026 | G24: 6245
A25: week 2 | B25: 2026-0008 | D25: 19500 | E25: 130 | F25: APRIL 11 - APRIL17 ,2026 | G25: 4955
A26: week 3 | F26: APRIL 18 - APRIL 24, 2026 | G26: 7910
A27: week 4 | B27: 2026-0019 | D27: 18120 | E27: 200 | F27: APRIL 25- MAY 1, 2026 | G27: 9520
A28: week 5
D30: =SUM(D24:D28) -> 45870 | E30: =SUM(E24:E28) -> 385 | G30: =SUM(G24:G28) -> 28630
B31: FUEL | F31: Salary | H31: Maintenance
A32: PM 7 | B32: PO No. / Ref | C32: DATE | D32: Amount | E32: Liter | F32: Date | G32: Amount | H32: Ref | I32: Description | J32: Amount
A33: week 1 | F33: APRIL 4 - APRIL 10 ,2026 | G33: 9150
A34: week 2 | B34: 2026-0009 | D34: 16500 | E34: 110 | F34: APRIL 11 - APRIL17 ,2026 | G34: 6250
A35: week 3 | B35: 2026-0015 | D35: 20392 | E35: 200 | F35: APRIL 18 - APRIL 24, 2026 | G35: 9440
A36: week 4 | F36: APRIL 25- MAY 1, 2026 | G36: 6710
A37: week 5
D39: =SUM(D33:D37) -> 36892 | E39: =SUM(E33:E37) -> 310 | G39: =SUM(G33:G37) -> 31550

Sheet May
A2: 46143
B3: FUEL | F3: Salary | H3: Maintenance
A4: PM 4 | B4: PO No. / Ref | C4: DATE | D4: Amount | E4: Liter | F4: Date | G4: Amount | H4: Ref | I4: Description | J4: Amount
A5: week 1 | F5: MAY 2-8,2026 | G5: 7655
A6: week 2 | B6: 2026-0023 | D6: 18120 | E6: 200 | F6: MAY 9-15,2026 | G6: 10620
A7: week 3 | F7: MAY 16-22,2026 | G7: 9660
A8: week 4 | B8: 2026-0026 | D8: 17606 | E8: 200 | F8: MAY 23-30,206 | G8: 10145
A9: week 5
D12: =SUM(D5:D9) -> 35726 | E12: =SUM(E5:E9) -> 400 | G12: =SUM(G5:G9) -> 38080
B13: FUEL | F13: Salary | H13: Maintenance
A14: PM 5 | B14: PO No. / Ref | C14: DATE | D14: Amount | E14: Liter | F14: Date | G14: Amount | H14: Ref | I14: Description | J14: Amount
A15: week 1 | B15: 2026-0022 | D15: 13590 | E15: 150 | F15: MAY 2-8,2026 | G15: 5570
A16: week 2 | F16: MAY 9-15,2026
A17: week 3 | F17: MAY 16-22,2026
A18: week 4 | F18: MAY 23-30,206
A19: week 5
D21: =SUM(D15:D19) -> 13590 | E21: =SUM(E15:E19) -> 150 | G21: =SUM(G15:G19) -> 5570
B22: FUEL | F22: Salary | H22: Maintenance
A23: PM 6 | B23: PO No. / Ref | C23: DATE | D23: Amount | E23: Liter | F23: Date | G23: Amount | H23: Ref | I23: Description | J23: Amount
A24: week 1 | F24: MAY 2-8,2026 | G24: 6425
A25: week 2 | B25: 2026-0024 | D25: 13590 | E25: 150 | F25: MAY 9-15,2026 | G25: 6550
A26: week 3 | B26: 2026-0025 | D26: 22007.5 | E26: 250 | F26: MAY 16-22,2026 | G26: 11300
A27: week 4 | B27: 2026-0028 | D27: 17606 | E27: 200 | F27: MAY 23-30,206 | G27: 3030
A28: week 5
D30: =SUM(D24:D28) -> 53203.5 | E30: =SUM(E24:E28) -> 600 | G30: =SUM(G24:G28) -> 27305
B31: FUEL | F31: Salary | H31: Maintenance
A32: PM 7 | B32: PO No. / Ref | C32: DATE | D32: Amount | E32: Liter | F32: Date | G32: Amount | H32: Ref | I32: Description | J32: Amount
A33: week 1 | F33: MAY 2-8,2026 | G33: 9365
A34: week 2 | B34: 2026-0030 | D34: 22650 | E34: 250 | F34: MAY 9-15,2026 | G34: 10265
A35: week 3 | B35: 2026-0029 | D35: 17606 | E35: 200 | F35: MAY 16-22,2026 | G35: 7045
A36: week 4 | F36: MAY 23-30,206 | G36: 4650
A37: week 5
D39: =SUM(D33:D37) -> 40256 | E39: =SUM(E33:E37) -> 450 | G39: =SUM(G33:G37) -> 31325

Sheet JUNE
A2: 46174
B3: FUEL | F3: Salary | H3: Maintenance
A4: PM 4 | B4: PO No. / Ref | C4: DATE | D4: Amount | E4: Liter | F4: Date | G4: Amount | H4: Ref | I4: Description | J4: Amount
A5: week 1 | F5: MAY 30-JUNE 5,2026 | G5: 9595
A6: week 2 | B6: 2026-0033 | D6: 15754 | E6: 200 | F6: JUNE 6-JUNE 12,2027 | G6: 8940
A7: week 3 | D7: 15754 | E7: 200 | F7: JUNE 13-JUNE 19,2027 | G7: 11935
A8: week 4 | D8: 15754 | F8: JUNE 20-JUNE 26,2027 | G8: 8313
A9: week 5 | F9: JUNE 26- JULY 3,2026 | G9: 6910
D12: =SUM(D5:D9) -> 47262 | E12: =SUM(E5:E9) -> 400 | G12: =SUM(G5:G9) -> 45693
B13: FUEL | F13: Salary | H13: Maintenance
A14: PM 5 | B14: PO No. / Ref | C14: DATE | D14: Amount | E14: Liter | F14: Date | G14: Amount | H14: Ref | I14: Description | J14: Amount
A15: week 1 | F15: MAY 30-JUNE 5,2026 | G15: 6650
A16: week 2 | B16: 2026-0031 | D16: 15754 | E16: 200 | F16: JUNE 6-JUNE 12,2027 | G16: 10630
A17: week 3 | D17: 15754 | E17: 200 | F17: JUNE 13-JUNE 19,2027 | G17: 7155
A18: week 4 | F18: JUNE 20-JUNE 26,2027 | G18: 9468
A19: week 5
D21: =SUM(D15:D19) -> 31508 | E21: =SUM(E15:E19) -> 400 | G21: =SUM(G15:G19) -> 33903
B22: FUEL | F22: Salary | H22: Maintenance
A23: PM 6 | B23: PO No. / Ref | C23: DATE | D23: Amount | E23: Liter | F23: Date | G23: Amount | H23: Ref | I23: Description | J23: Amount
A24: week 1 | F24: MAY 30-JUNE 5,2026 | G24: 5070
A25: week 2 | D25: 15754 | E25: 200 | F25: JUNE 6-JUNE 12,2027
A26: week 3 | F26: JUNE 13-JUNE 19,2027
A27: week 4 | F27: JUNE 20-JUNE 26,2027
A28: week 5 | F28: JUNE 26- JULY 3,2026 | G28: 5950
D30: =SUM(D24:D28) -> 15754 | E30: =SUM(E24:E28) -> 200 | G30: =SUM(G24:G28) -> 11020
B31: FUEL | F31: Salary | H31: Maintenance
A32: PM 7 | B32: PO No. / Ref | C32: DATE | D32: Amount | E32: Liter | F32: Date | G32: Amount | H32: Ref | I32: Description | J32: Amount
A33: week 1 | F33: MAY 30-JUNE 5,2026 | G33: 6750
A34: week 2 | B34: 2026-0032 | D34: 15754 | E34: 200 | F34: JUNE 6-JUNE 12,2027 | G34: 11640
A35: week 3 | D35: 15754 | E35: 200 | F35: JUNE 13-JUNE 19,2027 | G35: 7900
A36: week 4 | D36: 15754 | E36: 200 | F36: JUNE 20-JUNE 26,2027 | G36: 8008
A37: week 5 | D37: 14758 | E37: 200 | F37: JUNE 26- JULY 3,2026 | G37: 9815
D39: =SUM(D33:D37) -> 62020 | E39: =SUM(E33:E37) -> 800 | G39: =SUM(G33:G37) -> 44113

Sheet JULY
A2: 46204
B3: FUEL | G3: Salary | I3: Maintenance
A4: PM 4 | B4: PO No. / Ref | C4: DATE | D4: Amount | E4: Liter | F4: PRICE/LITER | G4: Date | H4: Amount | I4: Ref | J4: Description | K4: Amount
A5: week 1 | D5: =E5*F5 -> 11068.5 | E5: 150 | F5: 73.79 | G5: JULY 4-JULY 10,2026 | H5: 10570
A6: week 2 | D6: 14758 | E6: 200 | G6: JULY 11-JULY 17,2026 | H6: 6900
A7: week 3 | G7: JULY 18 -JULY 24,2026 | H7: 9065
A8: week 4 | D8: 16064 | E8: 200 | G8: JULY 25-JULY 31,2026 | H8: 9920
A9: week 5
D12: =SUM(D5:D9) -> 41890.5 | E12: =SUM(E5:E9) -> 550 | H12: =SUM(H5:H9) -> 36455
B13: FUEL | G13: Salary | I13: Maintenance
A14: PM 5 | B14: PO No. / Ref | C14: DATE | D14: Amount | E14: Liter | F14: PRICE/LITER | G14: Date | H14: Amount | I14: Ref | J14: Description | K14: Amount
A15: week 1 | G15: JULY 4-JULY 10,2026 | H15: 7855
A16: week 2 | D16: 18152.34 | E16: 246 | G16: JULY 11-JULY 17,2026 | H16: 2320
A17: week 3 | D17: 12048 | E17: 150 | G17: JULY 18 -JULY 24,2026 | H17: 4535
A18: week 4 | D18: 12048 | E18: 150 | G18: JULY 25-JULY 31,2026 | H18: 9165
A19: week 5
D21: =SUM(D15:D19) -> 42248.34 | E21: =SUM(E15:E19) -> 546 | H21: =SUM(H15:H19) -> 23875
B22: FUEL | G22: Salary | I22: Maintenance
A23: PM 6 | B23: PO No. / Ref | C23: DATE | D23: Amount | E23: Liter | F23: PRICE/LITER | G23: Date | H23: Amount | I23: Ref | J23: Description | K23: Amount
A24: week 1 | D24: 11068.5 | E24: 150 | G24: JULY 4-JULY 10,2026 | H24: 9690
A25: week 2 | D25: =E25*F25 -> 11068.5 | E25: 150 | F25: 73.79 | G25: JULY 11-JULY 17,2026 | H25: 7160
A26: week 3 | G26: JULY 18 -JULY 24,2026 | H26: 11490
A27: week 4 | D27: 19923 | E27: 270 | G27: JULY 25-JULY 31,2026 | H27: 8660
A28: week 5
D30: =SUM(D24:D28) -> 42060 | E30: =SUM(E24:E28) -> 570 | H30: =SUM(H24:H28) -> 37000
B31: FUEL | G31: Salary | I31: Maintenance
A32: PM 7 | B32: PO No. / Ref | C32: DATE | D32: Amount | E32: Liter | F32: PRICE/LITER | G32: Date | H32: Amount | I32: Ref | J32: Description | K32: Amount
A33: week 1 | D33: =E33*F33 -> 14758 | E33: 200 | F33: 73.79 | G33: JULY 4-JULY 10,2026
A34: week 2 | G34: JULY 11-JULY 17,2026 | H34: 4535
A35: week 3 | G35: JULY 18 -JULY 24,2026 | H35: 3905
A36: week 4 | D36: 16064 | G36: JULY 25-JULY 31,2026 | H36: 6695
A37: week 5
D39: =SUM(D33:D37) -> 30822 | E39: =SUM(E33:E37) -> 200 | H39: =SUM(H33:H37) -> 15135

Sheet AUG
A2: 46235
B3: FUEL | H3: Salary | J3: Maintenance
A4: PM 4 | B4: PO No. / Ref | C4: DATE | D4: Amount | E4: Liter | F4: PRICE/LITER | H4: Date | I4: Amount | J4: Ref | K4: Description | L4: Amount
A5: week 1 | B5: 2026-0065 | D5: =E5*F5 -> 16064 | E5: 200 | F5: 80.32 | H5: AUG 1-AUG 7 2026 | I5: 8080
B6: 2026-0068 | D6: =E6*F6 -> 16064 | E6: 200 | F6: 80.32 | G6: SAN VICENTE
D7: =SUM(D5:D6) -> 32128
A8: week 2 | H8: AUG 8-AUG 14 2026 | I8: 5350
A9: week 3 | D9: =E9*F9 -> 16064 | E9: 200 | F9: 80.32 | G9: ABORLAN | H9: AUG 15-AUG 21 2026 | I9: 8118
A10: week 4 | D10: =E10*F10 -> 16064 | E10: 200 | F10: 80.32 | G10: 2-40FTR ABORLAN | H10: AUG 22-AUG 28 2026 | I10: 6700
A11: week 5
D14: =SUM(D5:D11) -> 96384 | E14: =SUM(E5:E11) -> 800 | I14: =SUM(I5:I11) -> 28248
B15: FUEL | H15: Salary | J15: Maintenance
A16: PM 5 | B16: PO No. / Ref | C16: DATE | D16: Amount | E16: Liter | F16: PRICE/LITER | H16: Date | I16: Amount | J16: Ref | K16: Description | L16: Amount
A17: week 1 | H17: AUG 1-AUG 7 2026 | I17: 3350
A18: week 2 | B18: 2026-0072 | D18: =E18*F18 -> 16064 | E18: 200 | F18: 80.32 | G18: BROOKES PT | H18: AUG 8-AUG 14 2026 | I18: 5690
A19: week 3 | D19: =E19*F19 -> 12048 | E19: 150 | F19: 80.32 | G19: ELNIDO | H19: AUG 15-AUG 21 2026 | I19: 9678
A20: week 4 | G20: QUEZON | H20: AUG 22-AUG 28 2026 | I20: 5995
A21: week 5
D23: =SUM(D17:D21) -> 28112 | E23: =SUM(E17:E21) -> 350 | I23: =SUM(I17:I21) -> 24713
B24: FUEL | H24: Salary | J24: Maintenance
A25: PM 6 | B25: PO No. / Ref | C25: DATE | D25: Amount | E25: Liter | F25: PRICE/LITER | H25: Date | I25: Amount | J25: Ref | K25: Description | L25: Amount
A26: week 1 | B26: 2026-0066 | C26: 37834 | D26: =E26*F26 -> 12770.88 | E26: 159 | F26: 80.32 | H26: AUG 1-AUG 7 2026 | I26: 8865
B27: 2026-0069 | C27: 38565 | D27: =E27*F27 -> 12048 | E27: 150 | F27: 80.32 | G27: BROOKES PT
A28: week 2 | B28: 2026-0070 | C28: 39295 | D28: =E28*F28 -> 16064 | E28: 200 | F28: 80.32 | G28: ELNIDO | H28: AUG 8-AUG 14 2026 | I28: 7968
A29: week 3 | C29: 41487 | D29: =E29*F29 -> 12048 | E29: 150 | F29: 80.32 | H29: AUG 15-AUG 21 2026 | I29: 8660
A30: week 4 | H30: AUG 22-AUG 28 2026 | I30: 3080
A31: week 5
D34: =SUM(D26:D32) -> 52930.88 | E34: =SUM(E26:E32) -> 659 | I34: =SUM(I26:I32) -> 28573
B35: FUEL | H35: Salary | J35: Maintenance
A36: PM 7 | B36: PO No. / Ref | C36: DATE | D36: Amount | E36: Liter | F36: PRICE/LITER | H36: Date | I36: Amount | J36: Ref | K36: Description | L36: Amount
A37: week 1 | B37: 2026-0064 | C37: 37469 | D37: =E37*F37 -> 16064 | E37: 200 | F37: 80.32 | H37: AUG 1-AUG 7 2026 | I37: 8870
A38: week 2 | B38: 2026-0073 | C38: 39661 | D38: =E38*F38 -> 16064 | E38: 200 | F38: 80.32 | G38: ABORLAN | H38: AUG 8-AUG 14 2026 | I38: 7015
A39: week 3 | D39: =E39*F39 -> 8032 | E39: 100 | F39: 80.32 | G39: ELNIDO | H39: AUG 15-AUG 21 2026 | I39: 9978
D40: =E40*F40 -> 16064 | E40: 200 | F40: 80.32 | G40: 2 NARRA
D41: =SUM(D39:D40) -> 24096
A42: week 4 | C42: AUG 20,2026 | D42: =E42*F42 -> 12048 | E42: 150 | F42: 80.32 | G42: QUEZON | H42: AUG 22-AUG 28 2026 | I42: 8415
A43: week 5
D45: =SUM(D37:D43) -> 92368 | E45: =SUM(E37:E43) -> 850 | I45: =SUM(I37:I43) -> 34278

Sheet SEPT
A2: SEPT 26
B3: FUEL | H3: Salary | J3: Maintenance
A4: PM 4 | B4: PO No. / Ref | C4: DATE | D4: Amount | E4: Liter | F4: PRICE/LITER | H4: Date | I4: Amount | J4: Ref | K4: Description | L4: Amount
A5: week 1 | C5: 8/30/2026 | D5: =E5*F5 -> 19110 | E5: 200 | F5: 95.55 | G5: EL NIDO 40 FTR | H5: Aug 29-Sept 4 | I5: 11045
A6: week 2 | C6: 46182 | D6: =E6*F6 -> 27516 | E6: 300 | F6: 91.72 | G6: ELNIDO/SAN VICENTE | H6: Sept 5 -Sept 11 | I6: 8360
A7: week 3 | H7: Sept 12 -Sept 18
A8: week 4 | H8: Sept 19 -Sept 25
A9: week 5 | H9: Sept 26 -Oct 2
D14: =SUM(D5:D11) -> 46626 | E14: =SUM(E5:E11) -> 500 | I14: =SUM(I5:I11) -> 19405
B15: FUEL | H15: Salary | J15: Maintenance
A16: PM 5 | B16: PO No. / Ref | C16: DATE | D16: Amount | E16: Liter | F16: PRICE/LITER | H16: Date | I16: Amount | J16: Ref | K16: Description | L16: Amount
A17: week 1 | C17: 47331 | D17: =E17*F17 -> 9555 | E17: 100 | F17: 95.55 | G17: SAN VICENTE | H17: Aug 29-Sept 4 | I17: 5940
A18: week 2 | H18: Sept 5 -Sept 11 | I18: 3530
A19: week 3 | H19: Sept 12 -Sept 18
A20: week 4 | H20: Sept 19 -Sept 25
A21: week 5 | H21: Sept 26 -Oct 2
D23: =SUM(D17:D21) -> 9555 | E23: =SUM(E17:E21) -> 100 | I23: =SUM(I17:I21) -> 9470
B24: FUEL | H24: Salary | J24: Maintenance
A25: PM 6 | B25: PO No. / Ref | C25: DATE | D25: Amount | E25: Liter | F25: PRICE/LITER | H25: Date | I25: Amount | J25: Ref | K25: Description | L25: Amount
A26: week 1 | C26: 8/31/2026 | D26: =E26*F26 -> 9555 | E26: 100 | F26: 95.55 | G26: ABORLAN | H26: Aug 29-Sept 4 | I26: 9025
A27: week 2 | C27: SEPT 9,2026 | D27: =E27*F27 -> 27516 | E27: 300 | F27: 91.72 | G27: SANVI 40FTR | H27: Sept 5 -Sept 11 | I27: 8990
A28: week 3 | H28: Sept 12 -Sept 18
A29: week 4 | H29: Sept 19 -Sept 25
A30: week 5 | H30: Sept 26 -Oct 2
D34: =SUM(D26:D32) -> 37071 | E34: =SUM(E26:E32) -> 400 | I34: =SUM(I26:I32) -> 18015
B35: FUEL | H35: Salary | J35: Maintenance
A36: PM 7 | B36: PO No. / Ref | C36: DATE | D36: Amount | E36: Liter | F36: PRICE/LITER | H36: Date | I36: Amount | J36: Ref | K36: Description | L36: Amount
A37: week 1 | D37: =E37*F37 -> 0 | H37: Aug 29-Sept 4 | I37: 4840
A38: week 2 | D38: =E38*F38 -> 27516 | E38: 300 | F38: 91.72 | G38: ROXAS/SANVI | H38: Sept 5 -Sept 11 | I38: 9995
A39: week 3 | H39: Sept 12 -Sept 18
A40: week 4 | H40: Sept 19 -Sept 25
A41: week 5 | H41: Sept 26 -Oct 2
D45: =SUM(D37:D43) -> 27516 | E45: =SUM(E37:E43) -> 300 | I45: =SUM(I37:I43) -> 14835

Sheet Monthly
A2: PALAWAN TRANSPORT CORP
A3: MONTHLY KPI
A4: FOR THE YEAR 2026
A5: TARGET /WEEK 350,000
A8: UNIT | C8: MONTHY ACC REVENUE
C9: JANUARY | D9: FEBRUARY | E9: % | F9: MARCH | G9: % | H9: APRIL | I9: % | J9: MAY | K9: % | L9: JUNE | M9: % | N9: JULY | O9: % | P9: AUG | Q9: % | R9: SEPT
A10: PM 4 | B10: REVENUE | C10: ='[1]Weekly-January'!G10 -> #REF! | D10: ='[2]Weekly-February'!G10 -> #REF! | F10: ='Weekly-March'!D10 -> 347170 | H10: ='Weekly-April'!D10 -> 279115 | J10: ='Weekly-May'!D10 -> 255425 | L10: ='Weekly-June'!D10 -> 440395 | N10: ='Weekly-July'!D10 -> 325190 | P10: ='Weekly-Aug'!D10 -> 345550 | R10: ='Weekly-April'!N10 -> 0
B11: FUEL | D11: 49567.5 | E11: =D11/D10 -> #REF! | F11: ='Weekly-March'!D11 -> 45326.3 | G11: =F11/F10 -> 0.13055938 | H11: ='Weekly-April'!D11 -> 111498 | I11: =H11/H10 -> 0.39946975 | J11: ='Weekly-May'!D11 -> 35726 | K11: =J11/J10 -> 0.13986885 | L11: ='Weekly-June'!D11 -> 47262 | M11: =L11/L10 -> 0.10731729 | N11: ='Weekly-July'!D11 -> 41890.5 | O11: =N11/N10 -> 0.12881854 | P11: ='Weekly-Aug'!D11 -> 64256 | Q11: =P11/P10 -> 0.18595283 | R11: ='Weekly-April'!N11 -> 0
B12: SALARY | D12: 21650 | E12: =D12/D10 -> #REF! | F12: ='Weekly-March'!D12 -> 42268 | G12: =F12/F10 -> 0.12175015 | H12: ='Weekly-April'!D12 -> 23085 | I12: =H12/H10 -> 0.082707844 | J12: ='Weekly-May'!D12 -> 38080 | K12: =J12/J10 -> 0.14908486 | L12: ='Weekly-June'!D12 -> 38783 | M12: =L12/L10 -> 0.088064124 | N12: ='Weekly-July'!D12 -> 36455 | O12: =N12/N10 -> 0.11210369 | P12: ='Weekly-Aug'!D12 -> 28248 | Q12: =P12/P10 -> 0.081747938 | R12: ='Weekly-April'!N12 -> 0
B13: TRUCK DEPRECIATION | D13: 50000 | F13: 50000 | G13: =F13/F10 -> 0.14402166 | H13: 50000 | I13: =H13/H10 -> 0.17913763 | J13: 50000 | K13: =J13/J10 -> 0.19575218 | L13: 50000 | M13: =L13/L10 -> 0.11353444 | N13: 50000 | O13: =N13/N10 -> 0.15375627 | P13: 50000 | Q13: =P13/P10 -> 0.14469686 | R13: 50000
B14: MAINTENANCE | D14: 58000 | E14: =D14/D10 -> #REF! | F14: 58000 | G14: =F14/F10 -> 0.16706513 | H14: 58000 | I14: =H14/H10 -> 0.20779965 | J14: 58000 | K14: =J14/J10 -> 0.22707253 | L14: 58000 | M14: =L14/L10 -> 0.13169995 | N14: 58000 | O14: =N14/N10 -> 0.17835727 | P14: 58000 | Q14: =P14/P10 -> 0.16784836 | R14: 58000
B15: TOTAL EXPENSES | D15: =SUM(D11:D14) -> 179217.5 | E15: =D15/D10 -> #REF! | F15: =SUM(F11:F14) -> 195594.3 | G15: =F15/F10 -> 0.56339632 | H15: =SUM(H11:H14) -> 242583 | I15: =H15/H10 -> 0.86911488 | J15: =SUM(J11:J14) -> 181806 | K15: =J15/J10 -> 0.71177841 | L15: =SUM(L11:L14) -> 194045 | M15: =L15/L10 -> 0.44061581 | N15: =SUM(N11:N14) -> 186345.5 | O15: =N15/N10 -> 0.57303576 | P15: =SUM(P11:P14) -> 200504 | Q15: =P15/P10 -> 0.58024598 | R15: =SUM(R11:R14) -> 108000
B16: TOTAL GROSS INCOME (Actual) | D16: 100065.5 | E16: =D16/D10 -> #REF! | F16: ='Weekly-March'!D16 -> 124575.7 | G16: =F16/F10 -> 0.35883198 | H16: ='Weekly-April'!D16 -> 36532 | I16: =H16/H10 -> 0.13088512 | J16: ='Weekly-Aug'!E16 -> 0.41975402 | K16: =J16/J10 -> 1.6433553e-06 | L16: ='Weekly-April'!H16 -> -18125 | M16: =L16/L10 -> -0.041156235 | N16: ='Weekly-April'!J16 -> 56693 | O16: =N16/N10 -> 0.17433808 | P16: ='Weekly-Aug'!L16 -> 0 | Q16: =P16/P10 -> 0 | R16: ='Weekly-April'!N16 -> 0
B17: TARGET GROSS INCOME ( TARGET- 45%) | D17: ='Weekly-March'!D17 -> 156226.5 | E17: =D17/D10 -> #REF! | F17: ='Weekly-March'!D17 -> 156226.5 | G17: =F17/F10 -> 0.45 | H17: ='Weekly-April'!D17 -> 125601.75 | I17: =H17/H10 -> 0.45 | J17: ='Weekly-April'!E17 -> 0.45 | K17: =J17/J10 -> 1.7617696e-06 | L17: ='Weekly-April'!H17 -> 9969.75 | M17: =L17/L10 -> 0.0226382 | N17: ='Weekly-April'!J17 -> 44950.5 | O17: =N17/N10 -> 0.13822842 | P17: ='Weekly-Aug'!L17 -> 0 | Q17: =P17/P10 -> 0 | R17: ='Weekly-April'!N17 -> 0
B18: FAVORABLE ( UNFAVORABLE) | D18: =D16-D17 -> -56161 | F18: =F16-F17 -> -31650.8 | H18: =H16-H17 -> -89069.75 | J18: =J16-J17 -> -0.030245985 | L18: =L16-L17 -> -28094.75 | N18: =N16-N17 -> 11742.5 | P18: =P16-P17 -> 0 | R18: =R16-R17 -> 0
A20: PM 5 | B20: REVENUE | D20: 293150 | F20: ='Weekly-March'!D20 -> 293620 | H20: ='Weekly-April'!F20 -> 65150 | J20: ='Weekly-May'!D20 -> 36990 | L20: ='Weekly-April'!J20 -> 60470 | N20: ='Weekly-April'!L20 -> 0 | P20: ='Weekly-April'!N20 -> 0 | R20: ='Weekly-April'!P20 -> 0
B21: FUEL | D21: ='Weekly-March'!D21 -> 89043.9 | E21: =D21/D20 -> 0.30374859 | F21: ='Weekly-March'!D21 -> 89043.9 | G21: =F21/F20 -> 0.30326238 | H21: ='Weekly-April'!F21 -> 4500 | I21: =H21/H20 -> 0.069071374 | J21: ='Weekly-April'!G21 -> 0 | K21: =J21/J20 -> 0 | L21: ='Weekly-April'!J21 -> 0 | M21: =L21/L20 -> 0 | N21: ='Weekly-April'!L21 -> 0 | O21: =N21/N20 -> #DIV/0! | P21: ='Weekly-April'!N21 -> 0 | Q21: =P21/P20 -> #DIV/0! | R21: ='Weekly-April'!P21 -> 0
B22: SALARY | D22: ='Weekly-March'!D22 -> 38908 | E22: =D22/D20 -> 0.13272386 | F22: ='Weekly-March'!D22 -> 38908 | G22: =F22/F20 -> 0.13251141 | H22: ='Weekly-April'!F22 -> 4895 | I22: =H22/H20 -> 0.075134305 | J22: ='Weekly-April'!G22 -> 0 | K22: =J22/J20 -> 0 | L22: ='Weekly-April'!J22 -> 7750 | M22: =L22/L20 -> 0.12816273 | N22: ='Weekly-April'!L22 -> 0 | O22: =N22/N20 -> #DIV/0! | P22: ='Weekly-April'!N22 -> 0 | Q22: =P22/P20 -> #DIV/0! | R22: ='Weekly-April'!P22 -> 0
B23: TRUCK DEPRECIATION | D23: ='Weekly-March'!D23 -> 50000 | E23: =D23/D20 -> 0.17056115 | F23: 50000 | G23: =F23/F20 -> 0.17028813 | H23: 50000 | I23: =H23/H20 -> 0.76745971 | J23: 50000 | K23: =J23/J20 -> 1.3517167 | L23: 50000 | M23: =L23/L20 -> 0.82685629 | N23: 50000 | O23: =N23/N20 -> #DIV/0! | P23: 50000 | Q23: =P23/P20 -> #DIV/0! | R23: 50000
B24: MAINTENANCE | D24: ='Weekly-March'!D24 -> 58000 | E24: =D24/D20 -> 0.19785093 | F24: 58000 | G24: =F24/F20 -> 0.19753423 | H24: 58000 | I24: =H24/H20 -> 0.89025326 | J24: 58000 | K24: =J24/J20 -> 1.5679913 | L24: 58000 | M24: =L24/L20 -> 0.9591533 | N24: 58000 | O24: =N24/N20 -> #DIV/0! | P24: 58000 | Q24: =P24/P20 -> #DIV/0! | R24: 58000
B25: TOTAL EXPENSES | D25: =SUM(D21:D24) -> 235951.9 | E25: =D25/D20 -> 0.80488453 | F25: =SUM(F21:F24) -> 235951.9 | G25: =F25/F20 -> 0.80359614 | H25: =SUM(H21:H24) -> 117395 | I25: =H25/H20 -> 1.8019186 | J25: =SUM(J21:J24) -> 108000 | K25: =J25/J20 -> 2.919708 | L25: =SUM(L21:L24) -> 115750 | M25: =L25/L20 -> 1.9141723 | N25: =SUM(N21:N24) -> 108000 | O25: =N25/N20 -> #DIV/0! | P25: =SUM(P21:P24) -> 108000 | Q25: =P25/P20 -> #DIV/0! | R25: =SUM(R21:R24) -> 108000
B26: TOTAL GROSS INCOME (Actual) | D26: ='Weekly-March'!D26 -> 57668.1 | E26: =D26/D20 -> 0.19671874 | F26: =F20-F25 -> 57668.1 | G26: =F25/F20 -> 0.80359614 | H26: =H20-H25 -> -52245 | I26: =H25/H20 -> 1.8019186 | J26: =J20-J25 -> -71010 | K26: =J25/J20 -> 2.919708 | L26: =L20-L25 -> -55280 | M26: =L25/L20 -> 1.9141723 | N26: =N20-N25 -> -108000 | O26: =N25/N20 -> #DIV/0! | P26: =P20-P25 -> -108000 | Q26: =P25/P20 -> #DIV/0! | R26: =R20-R25 -> -108000
B27: TARGET GROSS INCOME ( TARGET- 45%) | D27: ='Weekly-March'!D27 -> 132129 | E27: =D27/D20 -> 0.45072147 | F27: =F20*0.45 -> 132129 | G27: =F27/F20 -> 0.45 | H27: =H20*0.45 -> 29317.5 | I27: =H27/H20 -> 0.45 | J27: =J20*0.45 -> 16645.5 | K27: =J27/J20 -> 0.45 | L27: =L20*0.45 -> 27211.5 | M27: =L27/L20 -> 0.45 | N27: =N20*0.45 -> 0 | O27: =N27/N20 -> #DIV/0! | P27: =P20*0.45 -> 0 | Q27: =P27/P20 -> #DIV/0! | R27: =R20*0.45 -> 0
B28: FAVORABLE ( UNFAVORABLE) | D28: =D26-D27 -> -74460.9 | F28: =F26-F27 -> -74460.9 | H28: =H26-H27 -> -81562.5 | J28: =J26-J27 -> -87655.5 | L28: =L26-L27 -> -82491.5 | N28: =N26-N27 -> -108000 | P28: =P26-P27 -> -108000 | R28: =R26-R27 -> -108000
A30: PM 6 | B30: REVENUE | C30: 71450 | D30: 212145 | F30: ='Weekly-March'!D30 -> 398870 | H30: ='Weekly-April'!F30 -> 119150 | J30: ='Weekly-May'!D30 -> 225885 | L30: ='Weekly-April'!J30 -> 65375 | N30: ='Weekly-April'!L30 -> 0 | P30: ='Weekly-April'!N30 -> 0 | R30: ='Weekly-April'!P30 -> 0
B31: FUEL | D31: 41284.25 | E31: =D31/D30 -> 0.19460393 | F31: ='Weekly-March'!D31 -> 113936.15 | G31: =F31/F30 -> 0.28564733 | H31: ='Weekly-April'!F31 -> 8250 | I31: =H31/H30 -> 0.069240453 | J31: ='Weekly-April'!G31 -> 0 | K31: =J31/J30 -> 0 | L31: ='Weekly-April'!J31 -> 0 | M31: =L31/L30 -> 0 | N31: ='Weekly-April'!L31 -> 0 | O31: =N31/N30 -> #DIV/0! | P31: ='Weekly-April'!N31 -> 0 | Q31: =P31/P30 -> #DIV/0! | R31: ='Weekly-April'!P31 -> 0
B32: SALARY | D32: 26933 | E32: =D32/D30 -> 0.12695562 | F32: ='Weekly-March'!D32 -> 37488 | G32: =F32/F30 -> 0.093985509 | H32: ='Weekly-April'!F32 -> 6245 | I32: =H32/H30 -> 0.052412925 | J32: ='Weekly-April'!G32 -> 0 | K32: =J32/J30 -> 0 | L32: ='Weekly-April'!J32 -> 7910 | M32: =L32/L30 -> 0.12099426 | N32: ='Weekly-April'!L32 -> 0 | O32: =N32/N30 -> #DIV/0! | P32: ='Weekly-April'!N32 -> 0 | Q32: =P32/P30 -> #DIV/0! | R32: ='Weekly-April'!P32 -> 0
B33: TRUCK DEPRECIATION | D33: 50000 | E33: =D33/D30 -> 0.23568786 | F33: 50000 | G33: =F33/F30 -> 0.12535413 | H33: 50000 | I33: =H33/H30 -> 0.41963911 | J33: 50000 | K33: =J33/J30 -> 0.22135157 | L33: 50000 | M33: =L33/L30 -> 0.76481836 | N33: 50000 | O33: =N33/N30 -> #DIV/0! | P33: 50000 | Q33: =P33/P30 -> #DIV/0! | R33: 50000
B34: MAINTENANCE | C34: 58000 | D34: 58000 | E34: =D34/D30 -> 0.27339791 | F34: 58000 | G34: =F34/F30 -> 0.14541079 | H34: 58000 | I34: =H34/H30 -> 0.48678137 | J34: 58000 | K34: =J34/J30 -> 0.25676782 | L34: 58000 | M34: =L34/L30 -> 0.88718929 | N34: 58000 | O34: =N34/N30 -> #DIV/0! | P34: 58000 | Q34: =P34/P30 -> #DIV/0! | R34: 58000
B35: TOTAL EXPENSES | D35: =SUM(D31:D34) -> 176217.25 | E35: =D35/D30 -> 0.83064531 | F35: =SUM(F31:F34) -> 259424.15 | G35: =F35/F30 -> 0.65039775 | H35: =SUM(H31:H34) -> 122495 | I35: =H35/H30 -> 1.0280739 | J35: =SUM(J31:J34) -> 108000 | K35: =J35/J30 -> 0.4781194 | L35: =SUM(L31:L34) -> 115910 | M35: =L35/L30 -> 1.7730019 | N35: =SUM(N31:N34) -> 108000 | O35: =N35/N30 -> #DIV/0! | P35: =SUM(P31:P34) -> 108000 | Q35: =P35/P30 -> #DIV/0! | R35: =SUM(R31:R34) -> 108000
B36: TOTAL GROSS INCOME (Actual) | D36: =D30-D35 -> 35927.75 | E36: =D36/D30 -> 0.16935469 | F36: ='Weekly-March'!D36 -> 139445.85 | G36: =F36/F30 -> 0.34960225 | H36: ='Weekly-April'!F36 -> 90155 | I36: =H36/H30 -> 0.75665128 | J36: ='Weekly-April'!G36 -> 0 | K36: =J36/J30 -> 0 | L36: ='Weekly-April'!J36 -> 42965 | M36: =L36/L30 -> 0.65720841 | N36: ='Weekly-April'!L36 -> 0 | O36: =N36/N30 -> #DIV/0! | P36: ='Weekly-April'!N36 -> 0 | Q36: =P36/P30 -> #DIV/0! | R36: ='Weekly-April'!P36 -> 0
B37: TARGET GROSS INCOME ( TARGET- 45%) | D37: =D30*0.45 -> 95465.25 | F37: =F30*0.45 -> 179491.5 | G37: =F37/F30 -> 0.45 | H37: =H30*0.45 -> 53617.5 | I37: =H37/H30 -> 0.45 | J37: =J30*0.45 -> 101648.25 | K37: =J37/J30 -> 0.45 | L37: =L30*0.45 -> 29418.75 | M37: =L37/L30 -> 0.45 | N37: =N30*0.45 -> 0 | O37: =N37/N30 -> #DIV/0! | P37: =P30*0.45 -> 0 | Q37: =P37/P30 -> #DIV/0! | R37: =R30*0.45 -> 0
B38: FAVORABLE ( UNFAVORABLE) | D38: =D36-D37 -> -59537.5 | F38: =SUM(F36-F37) -> -40045.65 | H38: =SUM(H36-H37) -> 36537.5 | J38: =SUM(J36-J37) -> -101648.25 | L38: =SUM(L36-L37) -> 13546.25 | N38: =SUM(N36-N37) -> 0 | P38: =SUM(P36-P37) -> 0 | R38: =SUM(R36-R37) -> 0
A40: PM 7 | B40: REVENUE | C40: 168200 | D40: 272230 | F40: ='Weekly-March'!D40 -> 275905 | H40: ='Weekly-April'!F40 -> 92050 | J40: ='Weekly-May'!D40 -> 270620 | L40: ='Weekly-April'!J40 -> 52960 | N40: ='Weekly-April'!L40 -> 0 | P40: ='Weekly-April'!N40 -> 0 | R40: ='Weekly-April'!P40 -> 0
B41: FUEL | D41: 51106.4 | E41: =D41/D40 -> 0.18773243 | F41: =-'Weekly-March'!D41 -> -63508.75 | G41: =F41/F40 -> -0.2301834 | H41: =-'Weekly-April'!F41 -> 0 | I41: =H41/H40 -> 0 | J41: =-'Weekly-April'!G41 -> 0 | K41: =J41/J40 -> 0 | L41: =-'Weekly-April'!J41 -> -20392 | M41: =L41/L40 -> -0.38504532 | N41: =-'Weekly-April'!L41 -> 0 | O41: =N41/N40 -> #DIV/0! | P41: =-'Weekly-April'!N41 -> 0 | Q41: =P41/P40 -> #DIV/0! | R41: =-'Weekly-April'!P41 -> 0
B42: SALARY | D42: 26295 | E42: =D42/D40 -> 0.096591118 | F42: ='Weekly-March'!D43 -> 50000 | G42: =F42/F40 -> 0.1812218 | H42: ='Weekly-April'!F43 -> 12500 | I42: =H42/H40 -> 0.13579576 | J42: ='Weekly-April'!G43 -> 0 | K42: =J42/J40 -> 0 | L42: ='Weekly-April'!J43 -> 12500 | M42: =L42/L40 -> 0.23602719 | N42: ='Weekly-April'!L43 -> 0 | O42: =N42/N40 -> #DIV/0! | P42: ='Weekly-April'!N43 -> 0 | Q42: =P42/P40 -> #DIV/0! | R42: ='Weekly-April'!P43 -> 0
B43: TRUCK DEPRECIATION | D43: 50000 | E43: =D43/D40 -> 0.18366822 | F43: ='Weekly-March'!D43 -> 50000 | G43: =F43/F40 -> 0.1812218 | H43: ='Weekly-April'!F43 -> 12500 | I43: =H43/H40 -> 0.13579576 | J43: ='Weekly-April'!G43 -> 0 | K43: =J43/J40 -> 0 | L43: ='Weekly-April'!J43 -> 12500 | M43: =L43/L40 -> 0.23602719 | N43: ='Weekly-April'!L43 -> 0 | O43: =N43/N40 -> #DIV/0! | P43: ='Weekly-April'!N43 -> 0 | Q43: =P43/P40 -> #DIV/0! | R43: ='Weekly-April'!P43 -> 0
B44: MAINTENANCE | C44: 58000 | D44: 58000 | E44: =D44/D40 -> 0.21305514 | F44: ='Weekly-March'!J44 -> 14500 | G44: =F44/F40 -> 0.052554321 | H44: ='Weekly-April'!L44 -> 0 | I44: =H44/H40 -> 0 | J44: ='Weekly-April'!M44 -> 0 | K44: =J44/J40 -> 0 | L44: ='Weekly-April'!P44 -> 0 | M44: =L44/L40 -> 0 | N44: ='Weekly-April'!R44 -> 0 | O44: =N44/N40 -> #DIV/0! | P44: ='Weekly-April'!T44 -> 0 | Q44: =P44/P40 -> #DIV/0! | R44: ='Weekly-April'!V44 -> 0
B45: TOTAL EXPENSES | D45: =SUM(D41:D44) -> 185401.4 | E45: =D45/D40 -> 0.68104691 | F45: ='Weekly-March'!D44 -> 58000 | G45: =F45/F40 -> 0.21021728 | H45: ='Weekly-April'!F44 -> 14500 | I45: =H45/H40 -> 0.15752309 | J45: ='Weekly-April'!G44 -> 0 | K45: =J45/J40 -> 0 | L45: ='Weekly-April'!J44 -> 14500 | M45: =L45/L40 -> 0.27379154 | N45: ='Weekly-April'!L44 -> 0 | O45: =N45/N40 -> #DIV/0! | P45: ='Weekly-April'!N44 -> 0 | Q45: =P45/P40 -> #DIV/0! | R45: ='Weekly-April'!P44 -> 0
B46: TOTAL GROSS INCOME (Actual) | D46: 136828.6 | E46: =D46/D40 -> 0.50262131 | F46: =F40-F45 -> 217905 | G46: =F46/F40 -> 0.78978272 | H46: =H40-H45 -> 77550 | I46: =H46/H40 -> 0.84247691 | J46: =J40-J45 -> 270620 | K46: =J46/J40 -> 1 | L46: =L40-L45 -> 38460 | M46: =L46/L40 -> 0.72620846 | N46: =N40-N45 -> 0 | O46: =N46/N40 -> #DIV/0! | P46: =P40-P45 -> 0 | Q46: =P46/P40 -> #DIV/0! | R46: =R40-R45 -> 0
...

Sheet Weekly January
A2: PALAWAN TRANSPORT CORP
A3: KPI
A4: MONTH OF January 2026
A5: TARGET /WEEK 350,000
A6: GROSS PROFIT 45% 31,500
A8: UNIT | C8: MONTHY ACC REVENUE | E8: WEEKLY REVENUE | G8: WEEKLY REVENUE | I8: WEEKLY REVENUE
C9: JANUARY | D9: % | E9: 1st week | G9: 2nd week | I9: 3rd week | J9: 4th week
A10: PM 4 | B10: REVENUE | C10: 23469
B11: FUEL | C11: =SUM(E11:J11) -> 53911.1 | D11: =C11/C10 -> 2.2971196 | E11: =Jan!D5 -> 18414 | G11: =Jan!D6 -> 12086 | I11: =Jan!D8 -> 12526 | J11: =Jan!D9 -> 10885.1
B12: SALARY | C12: =SUM(E12:J12) -> 43820 | D12: =C12/C10 -> 1.8671439 | E12: =Jan!F5 -> 11220 | G12: =Jan!F6 -> 12770 | I12: =Jan!F7 -> 10545 | J12: =Jan!F8 -> 9285
B13: TRUCK DEPRECIATION | C13: 50000 | D13: =C13/C10 -> 2.13047 | E13: 12500 | G13: 12500 | I13: 12500 | J13: 12500
B14: MAINTENANCE | C14: 58000 | D14: =C14/C10 -> 2.4713452 | E14: 14500 | G14: 14500 | I14: 14500 | J14: 14500
B15: TOTAL EXPENSES | C15: =SUM(C11:C14) -> 205731.1 | D15: =C15/C10 -> 8.7660787 | E15: =SUM(E11:E14) -> 56634 | G15: =SUM(G11:G14) -> 51856 | I15: =SUM(I11:I14) -> 50071 | J15: =SUM(J11:J14) -> 47170.1
B16: TOTAL GROSS INCOME (Actual) | C16: =C10-C15 -> -182262.1 | D16: =C16/C10 -> -7.7660787 | E16: =SUM(E10-E11-E12-E14) -> -44134 | G16: =SUM(G10-G11-G12-G14) -> -39356 | I16: =SUM(I10-I11-I12-I14) -> -37571
B17: TARGET GROSS INCOME ( TARGET- 45%) | C17: =C10*0.45 -> 10561.05 | D17: =C17/C10 -> 0.45 | E17: =E10*0.45 -> 0 | G17: =G10*0.45 -> 0 | I17: =I10*0.45 -> 0
B18: FAVORABLE ( UNFAVORABLE) | C18: =C16-C17 -> -192823.15 | E18: =E16-E17 -> -44134 | G18: =G16-G17 -> -39356 | I18: =I16-I17 -> -37571
A20: PM 5 | B20: REVENUE | C20: 261300
B21: FUEL | C21: =SUM(E21:I21) -> 33551.5 | D21: =C21/C20 -> 0.12840222 | E21: =Jan!D15 -> 18414 | G21: =Jan!D16 -> 6043 | I21: =Jan!D17 -> 9094.5 | J21: =Jan!D18 -> 12126
B22: SALARY | C22: =SUM(E22:I22) -> 25700 | D22: =C22/C20 -> 0.098354382 | E22: =Jan!F15 -> 8255 | G22: =Jan!F16 -> 7300 | I22: =Jan!F17 -> 10145 | J22: =Jan!F18 -> 10760
B23: TRUCK DEPRECIATION | C23: 50000 | D23: =C23/C20 -> 0.19135094 | E23: 12500 | G23: 12500 | I23: 12500
B24: MAINTENANCE | C24: 58000 | D24: =C24/C20 -> 0.22196709 | E24: 14500 | G24: 14500 | I24: 14500
B25: TOTAL EXPENSES | C25: =SUM(C21:C24) -> 167251.5 | D25: =C25/C20 -> 0.64007463 | E25: =SUM(E21:E24) -> 53669 | G25: =SUM(G21:G24) -> 40343 | I25: =SUM(I21:I24) -> 46239.5
B26: TOTAL GROSS INCOME (Actual) | C26: =C20-C25 -> 94048.5 | E26: =SUM(E20-E21-E22-E24) -> -41169 | G26: =SUM(G20-G21-G22-G24) -> -27843 | I26: =SUM(I20-I21-I22-I24) -> -33739.5
B27: TARGET GROSS INCOME ( TARGET- 45%) | C27: =C20*0.45 -> 117585 | E27: =E20*0.45 -> 0 | G27: =G20*0.45 -> 0 | I27: =I20*0.45 -> 0
B28: FAVORABLE ( UNFAVORABLE) | C28: =C26-C27 -> -23536.5 | E28: =E26-E27 -> -41169 | G28: =G26-G27 -> -27843 | I28: =I26-I27 -> -33739.5
A30: PM 6 | B30: REVENUE | C30: 71450
B31: FUEL | C31: =SUM(E31:I31) -> 16007.5 | I31: =Jan!D27 -> 16007.5 | J31: =Jan!D28 -> 9604.5
B32: SALARY | C32: =SUM(E32:I32) -> 2315 | I32: =Jan!F27 -> 2315 | J32: =Jan!F28 -> 11720
B33: TRUCK DEPRECIATION | C33: 50000 | E33: 12500 | G33: 12500 | I33: 12500 | J33: 12500
B34: MAINTENANCE | C34: 58000 | E34: 14500 | G34: 14500 | I34: 14500 | J34: 14500
B35: TOTAL EXPENSES | C35: =SUM(C31:C34) -> 126322.5 | E35: =SUM(E31:E34) -> 27000 | G35: =SUM(G31:G34) -> 27000 | I35: =SUM(I31:I34) -> 45322.5 | J35: =SUM(J31:J34) -> 48324.5
B36: TOTAL GROSS INCOME (Actual) | C36: =SUM(E36:I36) -> -61822.5 | E36: =SUM(E30-E31-E32-E34) -> -14500 | G36: =SUM(G30-G31-G32-G34) -> -14500 | I36: =SUM(I30-I31-I32-I34) -> -32822.5
B37: TARGET GROSS INCOME ( TARGET- 45%) | C37: =C30*0.45 -> 32152.5 | E37: =E30*0.45 -> 0 | G37: =G30*0.45 -> 0 | I37: =I30*0.45 -> 0
B38: FAVORABLE ( UNFAVORABLE) | C38: =SUM(C36-C37) -> -93975 | E38: =SUM(E36-E37) -> -14500 | G38: =SUM(G36-G37) -> -14500 | I38: =SUM(I36-I37) -> -32822.5
A40: PM 7 | B40: REVENUE | C40: 168200
B41: FUEL | C41: =SUM(E41:J41) -> 43073.5 | E41: =Jan!D35 -> 21483 | G41: =Jan!D36 -> 9064.5 | J41: =Jan!D38 -> 12526
B42: SALARY | C42: =SUM(E42:J42) -> 35085 | E42: =Jan!F35 -> 8355 | G42: =Jan!F36 -> 7110 | I42: =Jan!F37 -> 10785 | J42: =Jan!F38 -> 8835
B43: TRUCK DEPRECIATION | C43: 50000 | E43: 12500 | G43: 12500 | I43: 12500
B44: MAINTENANCE | C44: 58000 | E44: 14500 | G44: 14500 | I44: 14500
B45: TOTAL EXPENSES | C45: =SUM(C41:C44) -> 186158.5 | E45: =SUM(E41:E44) -> 56838 | G45: =SUM(G41:G44) -> 43174.5 | I45: =SUM(I41:I44) -> 37785
...

Sheet Weekly-February
A2: PALAWAN TRANSPORT CORP
A3: KPI
A4: MONTH OF February 2026
A5: TARGET /WEEK 350,000
A6: GROSS PROFIT 45% 31,500
A8: UNIT | E8: WEEKLY REVENUE | G8: WEEKLY REVENUE | I8: WEEKLY REVENUE
C9: FEBRUARY | D9: % | E9: 1st week | G9: 2nd week | I9: 3rd week | J9: 4th week
A10: PM 4 | B10: REVENUE | C10: 258345
B11: FUEL | C11: 49567.5 | D11: =C11/C10 -> 0.19186553 | E11: =Feb!D5 -> 13126 | G11: =Feb!D6 -> 13326 | I11: =Feb!D7 -> 10129 | J11: =Feb!D8 -> 12986
B12: SALARY | C12: 21650 | D12: =C12/C10 -> 0.083802667 | E12: =Feb!F5 -> 11985 | I12: =Feb!F7 -> 5590 | J12: =Feb!F8 -> 5400
B13: TRUCK DEPRECIATION | C13: 50000 | E13: 12500 | G13: 12500 | I13: 12500 | J13: 12500
B14: MAINTENANCE | C14: 58000 | D14: =C14/C10 -> 0.22450599 | E14: 14500 | G14: 14500 | I14: 14500 | J14: 14500
B15: TOTAL EXPENSES | C15: =SUM(C11:C14) -> 179217.5 | D15: =C15/C10 -> 0.69371383 | E15: =SUM(E11:E14) -> 52111 | G15: =SUM(G11:G14) -> 40326 | I15: =SUM(I11:I14) -> 42719 | J15: =SUM(J11:J14) -> 45386
B16: TOTAL GROSS INCOME (Actual) | C16: 100065.5 | D16: =C16/C10 -> 0.38733283 | E16: =SUM(E10-E11-E12-E14) -> -39611 | G16: =SUM(G10-G11-G12-G14) -> -27826 | I16: =SUM(I10-I11-I12-I14) -> -30219
B17: TARGET GROSS INCOME ( TARGET- 45%) | C17: =C10*0.45 -> 116255.25 | D17: =C17/C10 -> 0.45 | E17: =E10*0.45 -> 0 | G17: =G10*0.45 -> 0 | I17: =I10*0.45 -> 0
B18: FAVORABLE ( UNFAVORABLE) | C18: =C16-C17 -> -16189.75 | E18: =E16-E17 -> -39611 | G18: =G16-G17 -> -27826 | I18: =I16-I17 -> -30219
A20: PM 5 | B20: REVENUE | C20: 293150
B21: FUEL | C21: 39488 | D21: =C21/C20 -> 0.13470237 | G21: =Feb!D16 -> 6563 | I21: =Feb!D17 -> 12506 | J21: =Feb!D18 -> 19419
B22: SALARY | C22: 29063 | D22: =C22/C20 -> 0.099140372 | E22: =Feb!F15 -> 7045 | I22: =Feb!F17 -> 12052.8 | J22: =Feb!F18 -> 8555
B23: TRUCK DEPRECIATION | C23: 50000 | D23: =C23/C20 -> 0.17056115 | E23: 12500 | G23: 12500 | I23: 12500 | J23: 12500
B24: MAINTENANCE | C24: 58000 | D24: =C24/C20 -> 0.19785093 | E24: 14500 | G24: 14500 | I24: 14500 | J24: 14500
B25: TOTAL EXPENSES | C25: =SUM(C21:C24) -> 176551 | D25: =C25/C20 -> 0.60225482 | E25: =SUM(E21:E24) -> 34045 | G25: =SUM(G21:G24) -> 33563 | I25: =SUM(I21:I24) -> 51558.8 | J25: =SUM(J21:J24) -> 54974
B26: TOTAL GROSS INCOME (Actual) | C26: 166599 | D26: =C26/C20 -> 0.56830633 | E26: =SUM(E20-E21-E22-E24) -> -21545 | G26: =SUM(G20-G21-G22-G24) -> -21063 | I26: =SUM(I20-I21-I22-I24) -> -39058.8
B27: TARGET GROSS INCOME ( TARGET- 45%) | C27: =C20*0.45 -> 131917.5 | D27: =C27/C20 -> 0.45 | E27: =E20*0.45 -> 0 | G27: =G20*0.45 -> 0 | I27: =I20*0.45 -> 0
B28: FAVORABLE ( UNFAVORABLE) | C28: =C26-C27 -> 34681.5 | E28: =E26-E27 -> -21545 | G28: =G26-G27 -> -21063 | I28: =I26-I27 -> -39058.8
A30: PM 6 | B30: REVENUE | C30: 212145
B31: FUEL | C31: 41284.25 | D31: =C31/C30 -> 0.19460393 | E31: =Feb!D25 -> 11485.25 | I31: =Feb!D27 -> 16882.5 | J31: =Feb!D28 -> 12946
B32: SALARY | C32: 26933 | D32: =C32/C30 -> 0.12695562 | E32: =Feb!F25 -> 8460 | I32: =Feb!F27 -> 10403 | J32: =Feb!F28 -> 8360
B33: TRUCK DEPRECIATION | C33: 50000 | D33: =C33/C30 -> 0.23568786 | E33: 12500 | G33: 12500 | I33: 12500 | J33: 12500
B34: MAINTENANCE | C34: 58000 | D34: =C34/C30 -> 0.27339791 | E34: 14500 | G34: 14500 | I34: 14500 | J34: 14500
B35: TOTAL EXPENSES | C35: =SUM(C31:C34) -> 176217.25 | D35: =C35/C30 -> 0.83064531 | E35: =SUM(E31:E34) -> 46945.25 | G35: =SUM(G31:G34) -> 27000 | I35: =SUM(I31:I34) -> 54285.5
B36: TOTAL GROSS INCOME (Actual) | C36: =C30-C35 -> 35927.75 | D36: =C36/C30 -> 0.16935469 | E36: =SUM(E30-E31-E32-E34) -> -34445.25 | G36: =SUM(G30-G31-G32-G34) -> -14500 | I36: =SUM(I30-I31-I32-I34) -> -41785.5
B37: TARGET GROSS INCOME ( TARGET- 45%) | C37: =C30*0.45 -> 95465.25 | E37: =E30*0.45 -> 0 | G37: =G30*0.45 -> 0 | I37: =I30*0.45 -> 0
B38: FAVORABLE ( UNFAVORABLE) | C38: =C36-C37 -> -59537.5 | E38: =SUM(E36-E37) -> -34445.25 | G38: =SUM(G36-G37) -> -14500 | I38: =SUM(I36-I37) -> -41785.5
A40: PM 7 | B40: REVENUE | C40: 272230
B41: FUEL | C41: 51106.4 | D41: =C41/C40 -> 0.18773243 | E41: =Feb!D35 -> 24699.4 | G41: =Feb!D36 -> 13326 | I41: =Feb!D37 -> 12946 | J41: =Feb!D38 -> 9739.5
B42: SALARY | C42: 26295 | D42: =C42/C40 -> 0.096591118 | E42: =Feb!F35 -> 7955 | I42: =Feb!F37 -> 8095 | J42: =Feb!F38 -> 9365
B43: TRUCK DEPRECIATION | C43: 50000 | E43: 12500 | G43: 12500 | I43: 12500 | J43: 12500
B44: MAINTENANCE | C44: 58000 | D44: =C44/C40 -> 0.21305514 | E44: 14500 | G44: 14500 | I44: 14500 | J44: 14500
B45: TOTAL EXPENSES | C45: =SUM(C41:C44) -> 185401.4 | E45: =SUM(E41:E44) -> 59654.4 | G45: =SUM(G41:G44) -> 40326 | I45: =SUM(I41:I44) -> 48041
...

Sheet Weekly-March
B2: PALAWAN TRANSPORT CORP
B3: KPI
B4: MONTH OF MARCH 2026
B5: TARGET /WEEK 350,000
B6: GROSS PROFIT 45% 31,500
B8: UNIT | F8: WEEKLY REVENUE | H8: WEEKLY REVENUE | J8: WEEKLY REVENUE
D9: MARCH | E9: % | F9: 1st week | H9: 2nd week | J9: 3rd week | K9: 4th week | L9: 5th week
B10: PM 4 | C10: REVENUE | D10: =SUM(F10:L10) -> 347170 | F10: 71500 | H10: 93150 | J10: 69150 | K10: 56620 | L10: 56750
C11: FUEL | D11: =SUM(F11:L11) -> 45326.3 | E11: =D11/D10 -> 0.13055938 | F11: =March!D5 -> 10338.8 | H11: =March!D6 -> 21987.5 | K11: 13000
C12: SALARY | D12: =SUM(F12:L12) -> 42268 | E12: =D12/D10 -> 0.12175015 | F12: =March!F5 -> 10293 | H12: =March!F6 -> 12545 | J12: =March!F7 -> 7555 | K12: =March!F8 -> 6290 | L12: =March!F9 -> 5585
C13: TRUCK DEPRECIATION | D13: =SUM(F13:L13) -> 62500 | E13: =D13/D10 -> 0.18002708 | F13: 12500 | H13: 12500 | J13: 12500 | K13: 12500 | L13: 12500
C14: MAINTENANCE | D14: =SUM(F14:L14) -> 72500 | E14: =D14/D10 -> 0.20883141 | F14: 14500 | H14: 14500 | J14: 14500 | K14: 14500 | L14: 14500
C15: TOTAL EXPENSES | D15: =SUM(D11:D14) -> 222594.3 | E15: =D15/D10 -> 0.64116802 | F15: =SUM(F11:F14) -> 47631.8 | H15: =SUM(H11:H14) -> 61532.5 | J15: =SUM(J11:J14) -> 34555 | K15: =SUM(K11:K14) -> 46290 | L15: =SUM(L11:L14) -> 32585
C16: TOTAL GROSS INCOME (Actual) | D16: =D10-D15 -> 124575.7 | E16: =D16/D10 -> 0.35883198 | F16: =F10-F15 -> 23868.2 | H16: =H10-H15 -> 31617.5 | J16: =J10-J15 -> 34595 | K16: =K10-K15 -> 10330 | L16: =L10-L15 -> 24165
C17: TARGET GROSS INCOME ( TARGET- 45%) | D17: =D10*0.45 -> 156226.5 | E17: =D17/D10 -> 0.45 | F17: =F10*0.45 -> 32175 | H17: =H10*0.45 -> 41917.5 | J17: =J10*0.45 -> 31117.5 | K17: =K10*0.45 -> 25479 | L17: =L10*0.45 -> 25537.5
C18: FAVORABLE ( UNFAVORABLE) | D18: =D16-D17 -> -31650.8 | F18: =F16-F17 -> -8306.8 | H18: =H16-H17 -> -10300 | J18: =J16-J17 -> 3477.5 | K18: =K16-K17 -> -15149 | L18: =L16-L17 -> -1372.5
B20: PM 5 | C20: REVENUE | D20: =SUM(F20:L20) -> 293620 | F20: 52800 | H20: 25025 | J20: 59845 | K20: 92800 | L20: 63150
C21: FUEL | D21: =SUM(F21:L21) -> 89043.9 | E21: =D21/D20 -> 0.30326238 | F21: =March!D15 -> 14933.9 | J21: =March!D17 -> 16710 | K21: 23400 | L21: =March!D19 -> 34000
C22: SALARY | D22: =SUM(F22:L22) -> 38908 | E22: =D22/D20 -> 0.13251141 | F22: =March!F15 -> 8793 | H22: =March!F16 -> 5870 | J22: =March!F17 -> 8460 | K22: =March!F18 -> 9060 | L22: =March!F19 -> 6725
C23: TRUCK DEPRECIATION | D23: 50000 | E23: =D23/D20 -> 0.17028813 | F23: 12500 | H23: 12500 | J23: 12500 | K23: 12500 | L23: 12500
C24: MAINTENANCE | D24: 58000 | E24: =D24/D20 -> 0.19753423 | F24: 14500 | H24: 14500 | J24: 14500 | K24: 14500 | L24: 14500
C25: TOTAL EXPENSES | D25: =SUM(D21:D24) -> 235951.9 | E25: =D25/D20 -> 0.80359614 | F25: =SUM(F21:F24) -> 50726.9 | H25: =SUM(H21:H24) -> 32870 | J25: =SUM(J21:J24) -> 52170 | K25: =SUM(K21:K24) -> 59460 | L25: =SUM(L21:L24) -> 67725
C26: TOTAL GROSS INCOME (Actual) | D26: =D20-D25 -> 57668.1 | E26: =D26/D20 -> 0.19640386 | F26: =F20-F25 -> 2073.1 | H26: =H20-H25 -> -7845 | J26: =J20-J25 -> 7675 | K26: =K20-K25 -> 33340 | L26: =L20-L25 -> -4575
C27: TARGET GROSS INCOME ( TARGET- 45%) | D27: =D20*0.45 -> 132129 | E27: =D27/D20 -> 0.45 | F27: =F20*0.45 -> 23760 | H27: =H20*0.45 -> 11261.25 | J27: =J20*0.45 -> 26930.25 | K27: =K20*0.45 -> 41760 | L27: =L20*0.45 -> 28417.5
C28: FAVORABLE ( UNFAVORABLE) | D28: =D26-D27 -> -74460.9 | F28: =F26-F27 -> -21686.9 | H28: =H26-H27 -> -19106.25 | J28: =J26-J27 -> -19255.25 | K28: =K26-K27 -> -8420 | L28: =L26-L27 -> -32992.5
B30: PM 6 | C30: REVENUE | D30: =SUM(F30:L30) -> 398870 | F30: 129900 | H30: 40625 | J30: 68345 | K30: 46850 | L30: 113150
C31: FUEL | D31: =SUM(F31:L31) -> 113936.15 | E31: =D31/D30 -> 0.28564733 | F31: =March!D24 -> 21426.9 | J31: =March!D26 -> 18909.25 | K31: 48100 | L31: =March!D28 -> 25500
C32: SALARY | D32: =SUM(F32:L32) -> 37488 | E32: =D32/D30 -> 0.093985509 | F32: =March!F24 -> 11378 | H32: =March!F16 -> 5870 | J32: =March!F17 -> 8460 | K32: =March!F27 -> 7110 | L32: =March!F28 -> 4670
C33: TRUCK DEPRECIATION | D33: 50000 | E33: =D33/D30 -> 0.12535413 | F33: 12500 | H33: 12500 | J33: 12500 | K33: 12500 | L33: 12500
C34: MAINTENANCE | D34: 58000 | E34: =D34/D30 -> 0.14541079 | F34: 14500 | H34: 14500 | J34: 14500 | K34: 14500 | L34: 14500
C35: TOTAL EXPENSES | D35: =SUM(D31:D34) -> 259424.15 | E35: =D35/D30 -> 0.65039775 | F35: =SUM(F31:F34) -> 59804.9 | H35: =SUM(H31:H34) -> 32870 | J35: =SUM(J31:J34) -> 54369.25 | K35: =SUM(K31:K34) -> 82210 | L35: =SUM(L31:L34) -> 57170
C36: TOTAL GROSS INCOME (Actual) | D36: =D30-D35 -> 139445.85 | E36: =D36/D30 -> 0.34960225 | F36: =F30-F35 -> 70095.1 | H36: =H30-H35 -> 7755 | J36: =J30-J35 -> 13975.75 | K36: =K30-K35 -> -35360 | L36: =L30-L35 -> 55980
C37: TARGET GROSS INCOME ( TARGET- 45%) | D37: =D30*0.45 -> 179491.5 | E37: =D37/D30 -> 0.45 | F37: =F30*0.45 -> 58455 | H37: =H30*0.45 -> 18281.25 | J37: =J30*0.45 -> 30755.25 | K37: =K30*0.45 -> 21082.5 | L37: =L30*0.45 -> 50917.5
C38: FAVORABLE ( UNFAVORABLE) | D38: =SUM(D36-D37) -> -40045.65 | F38: =SUM(F36-F37) -> 11640.1 | H38: =SUM(H36-H37) -> -10526.25 | J38: =SUM(J36-J37) -> -16779.5 | K38: =SUM(K36-K37) -> -56442.5 | L38: =L36-L37 -> 5062.5
B40: PM 7 | C40: REVENUE | D40: =SUM(F40:L40) -> 275905 | F40: 80400 | H40: 56600 | J40: 58185 | K40: 48670 | L40: 32050
C41: FUEL | D41: =SUM(F41:L41) -> 63508.75 | E41: =D41/D40 -> 0.2301834 | F41: =March!D33 -> 19479 | J41: =March!D35 -> 18029.75 | K41: 26000
C42: SALARY | D42: =SUM(F42:L42) -> 41286 | E42: =D42/D40 -> 0.14963846 | F42: =March!F33 -> 9096.5 | H42: =March!F34 -> 8733.5 | J42: =March!F35 -> 10381 | K42: =March!F36 -> 7410 | L42: =March!F37 -> 5665
C43: TRUCK DEPRECIATION | D43: 50000 | E43: =D43/D40 -> 0.1812218 | F43: 12500 | H43: 12500 | J43: 12500 | K43: 12500 | L43: 12500
C44: MAINTENANCE | D44: 58000 | E44: =D44/D40 -> 0.21021728 | F44: 14500 | H44: 14500 | J44: 14500 | K44: 14500 | L44: 14500
C45: TOTAL EXPENSES | D45: =SUM(D41:D44) -> 212794.75 | E45: =D45/D40 -> 0.77126094 | F45: =SUM(F41:F44) -> 55575.5 | H45: =SUM(H41:H44) -> 35733.5 | J45: =SUM(J41:J44) -> 55410.75 | K45: =SUM(K41:K44) -> 60410 | L45: =SUM(L41:L44) -> 32665
...

Sheet Weekly-April
B2: PALAWAN TRANSPORT CORP
B3: KPI
B4: MONTH OF APRIL 2026
B5: TARGET /WEEK 350,000
B6: GROSS PROFIT 45% 31,500
B8: UNIT | F8: WEEKLY REVENUE | H8: WEEKLY REVENUE | J8: WEEKLY REVENUE
D9: APRIL | E9: % | F9: 1st week | H9: 2nd week | J9: 3rd week | K9: 4th week
B10: PM 4 | C10: REVENUE | D10: =SUM(F10:K10) -> 279115 | F10: 117950 | H10: 22155 | J10: 99890 | K10: 39120
C11: FUEL | D11: =SUM(F11:K11) -> 111498 | E11: =D11/D10 -> 0.39946975 | F11: ='April '!D5 -> 51000 | H11: ='April '!D6 -> 22500 | J11: ='April '!D7 -> 20392 | K11: =May!D8 -> 17606
C12: SALARY | D12: =SUM(F12:K12) -> 23085 | E12: =D12/D10 -> 0.082707844 | F12: ='April '!G5 -> 5360 | H12: ='April '!G6 -> 3280 | J12: ='April '!G7 -> 8305 | K12: ='April '!G8 -> 6140
C13: TRUCK DEPRECIATION | D13: 50000 | E13: =D13/D10 -> 0.17913763 | F13: 12500 | H13: 12500 | J13: 12500 | K13: 12500
C14: MAINTENANCE | D14: 58000 | E14: =D14/D10 -> 0.20779965 | F14: 14500 | H14: 14500 | J14: 14500 | K14: 14500
C15: TOTAL EXPENSES | D15: =SUM(D11:D14) -> 242583 | E15: =D15/D10 -> 0.86911488 | F15: =SUM(F11:F14) -> 83360 | H15: =SUM(H11:H14) -> 52780 | J15: =SUM(J11:J14) -> 55697 | K15: =SUM(K11:K14) -> 50746
C16: TOTAL GROSS INCOME (Actual) | D16: =D10-D15 -> 36532 | E16: =D16/D10 -> 0.13088512 | F16: =SUM(F10-F11-F12-F14) -> 47090 | H16: =SUM(H10-H11-H12-H14) -> -18125 | J16: =SUM(J10-J11-J12-J14) -> 56693 | K16: =SUM(K10-K11-K12-K13-K14) -> -11626
C17: TARGET GROSS INCOME ( TARGET- 45%) | D17: =D10*0.45 -> 125601.75 | E17: =D17/D10 -> 0.45 | F17: =F10*0.45 -> 53077.5 | H17: =H10*0.45 -> 9969.75 | J17: =J10*0.45 -> 44950.5 | K17: =K10*0.45 -> 17604
C18: FAVORABLE ( UNFAVORABLE) | D18: =D16-D17 -> -89069.75 | F18: =F16-F17 -> -5987.5 | H18: =H16-H17 -> -28094.75 | J18: =J16-J17 -> 11742.5 | K18: =K16-K17 -> -29230
B20: PM 5 | C20: REVENUE | D20: =SUM(F20:K20) -> 207205 | F20: 65150 | H20: 33655 | J20: 60470 | K20: 47930
C21: FUEL | D21: =SUM(F21:K21) -> 45120 | E21: =D21/D20 -> 0.21775536 | F21: ='April '!D15 -> 4500 | H21: ='April '!D16 -> 22500 | J21: =May!D17 -> 0 | K21: ='April '!D18 -> 18120
C22: SALARY | D22: =SUM(F22:K22) -> 23535 | E22: =D22/D20 -> 0.11358317 | F22: ='April '!G15 -> 4895 | H22: ='April '!G16 -> 4750 | J22: ='April '!G17 -> 7750 | K22: ='April '!G18 -> 6140
C23: TRUCK DEPRECIATION | D23: 50000 | E23: =D23/D20 -> 0.24130692 | F23: 12500 | H23: 12500 | J23: 12500 | K23: 12500
C24: MAINTENANCE | D24: 58000 | E24: =D24/D20 -> 0.27991603 | F24: 14500 | H24: 14500 | J24: 14500 | K24: 14500
C25: TOTAL EXPENSES | D25: =SUM(D21:D24) -> 176655 | E25: =D25/D20 -> 0.85256147 | F25: =SUM(F21:F24) -> 36395 | H25: =SUM(H21:H24) -> 54250 | J25: =SUM(J21:J24) -> 34750 | K25: =SUM(K21:K24) -> 51260
C26: TOTAL GROSS INCOME (Actual) | D26: =D20-D25 -> 30550 | E26: =D26/D20 -> 0.14743853 | F26: =SUM(F20-F21-F22-F24) -> 41255 | H26: =SUM(H20-H21-H22-H24) -> -8095 | J26: =SUM(J20-J21-J22-J24) -> 38220 | K26: =SUM(K20-K21-K22-K23-K24) -> -3330
C27: TARGET GROSS INCOME ( TARGET- 45%) | D27: =D20*0.45 -> 93242.25 | E27: =D27/D20 -> 0.45 | F27: =F20*0.45 -> 29317.5 | H27: =H20*0.45 -> 15144.75 | J27: =J20*0.45 -> 27211.5 | K27: =K20*0.45 -> 21568.5
C28: FAVORABLE ( UNFAVORABLE) | D28: =D26-D27 -> -62692.25 | F28: =F26-F27 -> 11937.5 | H28: =H26-H27 -> -23239.75 | J28: =J26-J27 -> 11008.5 | K28: =K26-K27 -> -24898.5
B30: PM 6 | C30: REVENUE | D30: =SUM(F30:K30) -> 275750 | F30: 119150 | H30: 10615 | J30: 65375 | K30: 80610
C31: FUEL | D31: =SUM(F31:K31) -> 45870 | E31: =D31/D30 -> 0.16634633 | F31: ='April '!D24 -> 8250 | H31: ='April '!D25 -> 19500 | J31: ='April '!B26 -> 0 | K31: ='April '!D27 -> 18120
C32: SALARY | D32: =SUM(F32:K32) -> 28630 | E32: =D32/D30 -> 0.10382593 | F32: ='April '!G24 -> 6245 | H32: ='April '!G25 -> 4955 | J32: ='April '!G26 -> 7910 | K32: ='April '!G27 -> 9520
C33: TRUCK DEPRECIATION | D33: 50000 | E33: =D33/D30 -> 0.18132366 | F33: 12500 | H33: 12500 | J33: 12500 | K33: 12500
C34: MAINTENANCE | D34: 58000 | E34: =D34/D30 -> 0.21033545 | F34: 14500 | H34: 14500 | J34: 14500 | K34: 14500
C35: TOTAL EXPENSES | D35: =SUM(D31:D34) -> 182500 | E35: =D35/D30 -> 0.66183137 | F35: =SUM(F31:F34) -> 41495 | H35: =SUM(H31:H34) -> 51455 | J35: =SUM(J31:J34) -> 34910 | K35: =K31:K31 -> 18120
C36: TOTAL GROSS INCOME (Actual) | D36: =SUM(F36:J36) -> 104780 | E36: =D36/D30 -> 0.37998187 | F36: =SUM(F30-F31-F32-F34) -> 90155 | H36: =SUM(H30-H31-H32-H34) -> -28340 | J36: =SUM(J30-J31-J32-J34) -> 42965 | K36: =SUM(K30-K31-K32-K33-K34) -> 25970
C37: TARGET GROSS INCOME ( TARGET- 45%) | D37: =D30*0.45 -> 124087.5 | E37: =D37/D30 -> 0.45 | F37: =F30*0.45 -> 53617.5 | H37: =H30*0.45 -> 4776.75 | J37: =J30*0.45 -> 29418.75 | K37: =K30*0.45 -> 36274.5
C38: FAVORABLE ( UNFAVORABLE) | D38: =SUM(D36-D37) -> -19307.5 | F38: =SUM(F36-F37) -> 36537.5 | H38: =SUM(H36-H37) -> -33116.75 | J38: =SUM(J36-J37) -> 13546.25 | K38: =K36-K37 -> -10304.5
B40: PM 7 | C40: REVENUE | D40: =SUM(F40:K40) -> 226860 | F40: 92050 | H40: 59370 | J40: 52960 | K40: 22480
C41: FUEL | D41: =SUM(F41:K41) -> 36892 | E41: =D41/D40 -> 0.16262012 | F41: ='April '!D333 -> 0 | H41: ='April '!D34 -> 16500 | J41: ='April '!D35 -> 20392 | K41: ='April '!D36 -> 0
C42: SALARY | D42: =SUM(F42:K42) -> 31550 | E42: =D42/D40 -> 0.13907256 | F42: ='April '!G33 -> 9150 | H42: ='April '!G34 -> 6250 | J42: ='April '!G35 -> 9440 | K42: ='April '!G36 -> 6710
C43: TRUCK DEPRECIATION | D43: 50000 | E43: =D43/D40 -> 0.22040025 | F43: 12500 | H43: 12500 | J43: 12500 | K43: 12500
C44: MAINTENANCE | D44: 58000 | E44: =D44/D40 -> 0.25566429 | F44: 14500 | H44: 14500 | J44: 14500 | K44: 14500
C45: TOTAL EXPENSES | D45: =SUM(D41:D44) -> 176442 | E45: =D45/D40 -> 0.77775721 | F45: =SUM(F41:F44) -> 36150 | H45: =SUM(H41:H44) -> 49750 | J45: =SUM(J41:J44) -> 56832 | K45: =SUM(K41:K41) -> 0
...

Sheet Weekly-May
B2: PALAWAN TRANSPORT CORP
B3: KPI
B4: MONTH OF MAY 2026
B5: TARGET /WEEK 350,000
B6: GROSS PROFIT 45% 31,500
B8: UNIT | F8: WEEKLY REVENUE | H8: WEEKLY REVENUE | J8: WEEKLY REVENUE
D9: MAY | E9: % | F9: 1st week | H9: 2nd week | J9: 3rd week | K9: 4th week
B10: PM 4 | C10: REVENUE | D10: =SUM(F10:K10) -> 255425 | F10: 70695 | H10: 129090 | J10: =-J11-J12-J13-J14 -> -36660 | K10: 92300
C11: FUEL | D11: =SUM(F11:K11) -> 35726 | E11: =D11/D10 -> 0.13986885 | F11: =May!D5 -> 0 | H11: =May!D6 -> 18120 | J11: =May!D7 -> 0 | K11: =May!D8 -> 17606
C12: SALARY | D12: =SUM(F12:K12) -> 38080 | E12: =D12/D10 -> 0.14908486 | F12: =May!G5 -> 7655 | H12: =May!G6 -> 10620 | J12: =May!G7 -> 9660 | K12: =May!G8 -> 10145
C13: TRUCK DEPRECIATION | D13: 50000 | E13: =D13/D10 -> 0.19575218 | F13: 12500 | H13: 12500 | J13: 12500 | K13: 12500
C14: MAINTENANCE | D14: 58000 | E14: =D14/D10 -> 0.22707253 | F14: 14500 | H14: 14500 | J14: 14500 | K14: 14500
C15: TOTAL EXPENSES | D15: =SUM(D11:D14) -> 181806 | E15: =D15/D10 -> 0.71177841 | F15: =SUM(F11:F14) -> 34655 | H15: =SUM(H11:H14) -> 55740 | J15: =SUM(J11:J14) -> 36660 | K15: =SUM(K11:K14) -> 54751
C16: TOTAL GROSS INCOME (Actual) | D16: =D10-D15 -> 73619 | E16: =D16/D10 -> 0.28822159 | F16: =SUM(F10-F11-F12-F14) -> 48540 | H16: {=_xleta.SUM} -> #NAME? | J16: {=_xleta.SUM} -> #NAME? | K16: =SUM(K10-K11-K12-K13-K14) -> 37549
C17: TARGET GROSS INCOME ( TARGET- 45%) | D17: =D10*0.45 -> 114941.25 | E17: =D17/D10 -> 0.45 | F17: =F10*0.45 -> 31812.75 | H17: =H10*0.45 -> 58090.5 | J17: =J10*0.45 -> -16497 | K17: =K10*0.45 -> 41535
C18: FAVORABLE ( UNFAVORABLE) | D18: =D16-D17 -> -41322.25 | F18: =F16-F17 -> 16727.25 | H18: =H16-H17 -> #NAME? | J18: =J16-J17 -> #NAME? | K18: =K16-K17 -> -3986
B20: PM 5 | C20: REVENUE | D20: =SUM(F20:K20) -> 36990 | F20: 36990
C21: FUEL | D21: =SUM(F21:K21) -> 13590 | E21: =D21/D20 -> 0.36739659 | F21: =May!D15 -> 13590 | H21: =May!D16 -> 0 | J21: =May!D17 -> 0 | K21: =May!D18 -> 0
C22: SALARY | D22: =SUM(F22:K22) -> 5570 | E22: =D22/D20 -> 0.15058124 | F22: =May!G15 -> 5570 | H22: =May!G16 -> 0 | J22: =May!G17 -> 0 | K22: =May!G18 -> 0
C23: TRUCK DEPRECIATION | D23: 50000 | E23: =D23/D20 -> 1.3517167 | F23: 12500 | H23: 12500 | J23: 12500 | K23: 12500
C24: MAINTENANCE | D24: 58000 | E24: =D24/D20 -> 1.5679913 | F24: 14500 | H24: 14500 | J24: 14500 | K24: 14500
C25: TOTAL EXPENSES | D25: =SUM(D21:D24) -> 127160 | E25: =D25/D20 -> 3.4376859 | F25: =SUM(F21:F24) -> 46160 | H25: =SUM(H21:H24) -> 27000 | J25: =SUM(J21:J24) -> 27000 | K25: =SUM(K21:K24) -> 27000
C26: TOTAL GROSS INCOME (Actual) | D26: =D20-D25 -> -90170 | E26: =D26/D20 -> -2.4376859 | F26: =SUM(F20-F21-F22-F24) -> 3330 | H26: =SUM(H20-H21-H22-H24) -> -14500 | J26: =SUM(J20-J21-J22-J24) -> -14500 | K26: =SUM(K20-K21-K22-K23-K24) -> -27000
C27: TARGET GROSS INCOME ( TARGET- 45%) | D27: =D20*0.45 -> 16645.5 | E27: =D27/D20 -> 0.45 | F27: =F20*0.45 -> 16645.5 | H27: =H20*0.45 -> 0 | J27: =J20*0.45 -> 0 | K27: =K20*0.45 -> 0
